<sdf version='1.6'>
  <model name='justina_simple'>
    <link name='base_link'>
      <pose frame=''>0 0 0 0 -0 0</pose>
      <inertial>
        <pose frame=''>0.000749 0 0.79 0 -0 0</pose>
        <mass>13.35</mass>
        <inertia>
          <ixx>3.92871</ixx>
          <ixy>0</ixy>
          <ixz>0.0035</ixz>
          <iyy>3.82934</iyy>
          <iyz>8.67362e-19</iyz>
          <izz>0.256562</izz>
        </inertia>
      </inertial>
      <collision name='base_link_collision'>
        <pose frame=''>0 0 0.235 0 -0 0</pose>
        <geometry>
          <box>
            <size>0.42 0.42 0.2</size>
          </box>
        </geometry>
      </collision>
      <collision name='base_link_fixed_joint_lump__laser_link_collision_1'>
        <pose frame=''>0.1 0 0.44 0 -0 0</pose>
        <geometry>
          <box>
            <size>0.08 0.08 0.1</size>
          </box>
        </geometry>
      </collision>
      <collision name='base_link_fixed_joint_lump__spine_link_collision_2'>
        <pose frame=''>0 0 0.41 0 -0 0</pose>
        <geometry>
          <box>
            <size>0.07 0.045 0.7</size>
          </box>
        </geometry>
      </collision>
      <collision name='base_link_fixed_joint_lump__waist_link_collision_3'>
        <pose frame=''>0 0 0.77 0 -0 0</pose>
        <geometry>
          <cylinder>
            <length>0.06</length>
            <radius>0.08</radius>
          </cylinder>
        </geometry>
      </collision>
      <collision name='base_link_fixed_joint_lump__waist_link_collision_4'>
        <pose frame=''>0 0 0.83 0 -0 0</pose>
        <geometry>
          <cylinder>
            <length>0.08</length>
            <radius>0.04</radius>
          </cylinder>
        </geometry>
      </collision>
      <collision name='base_link_fixed_joint_lump__waist_link_collision_5'>
        <pose frame=''>0 0 0.945 0 -0 0</pose>
        <geometry>
          <box>
            <size>0.055 0.08 0.15</size>
          </box>
        </geometry>
      </collision>
      <collision name='base_link_fixed_joint_lump__waist_link_collision_6'>
        <pose frame=''>0 0 1.105 0 -0 0</pose>
        <geometry>
          <cylinder>
            <length>0.17</length>
            <radius>0.02</radius>
          </cylinder>
        </geometry>
      </collision>
      <collision name='base_link_fixed_joint_lump__shoulders_link_collision_7'>
        <pose frame=''>0 0 1.23 3.14159 1.57079 3.14159</pose>
        <geometry>
          <box>
            <size>0.045 0.43 0.045</size>
          </box>
        </geometry>
      </collision>
      <collision name='base_link_fixed_joint_lump__shoulders_left_link_collision_8'>
        <pose frame=''>-0 0.23 1.195 3.14159 1.57079 3.14159</pose>
        <geometry>
          <box>
            <size>0.08 0.1 0.04</size>
          </box>
        </geometry>
      </collision>
      <collision name='base_link_fixed_joint_lump__shoulders_right_link_collision_9'>
        <pose frame=''>-0 -0.23 1.195 3.14159 1.57079 3.14159</pose>
        <geometry>
          <box>
            <size>0.08 0.1 0.04</size>
          </box>
        </geometry>
      </collision>
      <collision name='base_link_fixed_joint_lump__wheel_back_collision_10'>
        <pose frame=''>-0.24 0 0.065 1.5708 -0 1.5708</pose>
        <geometry>
          <cylinder>
            <length>0.04</length>
            <radius>0.06</radius>
          </cylinder>
        </geometry>
      </collision>
      <collision name='base_link_fixed_joint_lump__wheel_front_collision_11'>
        <pose frame=''>0.24 0 0.065 1.5708 -0 1.5708</pose>
        <geometry>
          <cylinder>
            <length>0.04</length>
            <radius>0.06</radius>
          </cylinder>
        </geometry>
      </collision>
      <collision name='base_link_fixed_joint_lump__wheel_left_collision_12'>
        <pose frame=''>0 -0.24 0.065 1.5708 -0 0</pose>
        <geometry>
          <cylinder>
            <length>0.04</length>
            <radius>0.06</radius>
          </cylinder>
        </geometry>
      </collision>
      <collision name='base_link_fixed_joint_lump__wheel_right_collision_13'>
        <pose frame=''>0 0.24 0.065 1.5708 -0 0</pose>
        <geometry>
          <cylinder>
            <length>0.04</length>
            <radius>0.06</radius>
          </cylinder>
        </geometry>
      </collision>
      <visual name='base_link_visual'>
        <pose frame=''>0 0 0.235 0 -0 0</pose>
        <geometry>
          <box>
            <size>0.42 0.42 0.2</size>
          </box>
        </geometry>
      </visual>
      <visual name='base_link_fixed_joint_lump__laser_link_visual_1'>
        <pose frame=''>0.1 0 0.44 0 -0 0</pose>
        <geometry>
          <box>
            <size>0.08 0.08 0.1</size>
          </box>
        </geometry>
      </visual>
      <visual name='base_link_fixed_joint_lump__spine_link_visual_2'>
        <pose frame=''>0 0 0.41 0 -0 0</pose>
        <geometry>
          <box>
            <size>0.07 0.045 0.7</size>
          </box>
        </geometry>
      </visual>
      <visual name='base_link_fixed_joint_lump__waist_link_visual_3'>
        <pose frame=''>0 0 0.77 0 -0 0</pose>
        <geometry>
          <cylinder>
            <length>0.06</length>
            <radius>0.08</radius>
          </cylinder>
        </geometry>
      </visual>
      <visual name='base_link_fixed_joint_lump__waist_link_visual_4'>
        <pose frame=''>0 0 0.83 0 -0 0</pose>
        <geometry>
          <cylinder>
            <length>0.08</length>
            <radius>0.04</radius>
          </cylinder>
        </geometry>
      </visual>
      <visual name='base_link_fixed_joint_lump__waist_link_visual_5'>
        <pose frame=''>0 0 0.945 0 -0 0</pose>
        <geometry>
          <box>
            <size>0.055 0.08 0.15</size>
          </box>
        </geometry>
      </visual>
      <visual name='base_link_fixed_joint_lump__waist_link_visual_6'>
        <pose frame=''>0 0 1.105 0 -0 0</pose>
        <geometry>
          <cylinder>
            <length>0.17</length>
            <radius>0.02</radius>
          </cylinder>
        </geometry>
      </visual>
      <visual name='base_link_fixed_joint_lump__shoulders_link_visual_7'>
        <pose frame=''>0 0 1.23 3.14159 1.57079 3.14159</pose>
        <geometry>
          <box>
            <size>0.045 0.43 0.045</size>
          </box>
        </geometry>
      </visual>
      <visual name='base_link_fixed_joint_lump__shoulders_left_link_visual_8'>
        <pose frame=''>-0 0.23 1.195 3.14159 1.57079 3.14159</pose>
        <geometry>
          <box>
            <size>0.08 0.1 0.04</size>
          </box>
        </geometry>
      </visual>
      <visual name='base_link_fixed_joint_lump__shoulders_right_link_visual_9'>
        <pose frame=''>-0 -0.23 1.195 3.14159 1.57079 3.14159</pose>
        <geometry>
          <box>
            <size>0.08 0.1 0.04</size>
          </box>
        </geometry>
      </visual>
      <visual name='base_link_fixed_joint_lump__wheel_back_visual_10'>
        <pose frame=''>-0.24 0 0.065 1.5708 -0 1.5708</pose>
        <geometry>
          <cylinder>
            <length>0.04</length>
            <radius>0.06</radius>
          </cylinder>
        </geometry>
      </visual>
      <visual name='base_link_fixed_joint_lump__wheel_front_visual_11'>
        <pose frame=''>0.24 0 0.065 1.5708 -0 1.5708</pose>
        <geometry>
          <cylinder>
            <length>0.04</length>
            <radius>0.06</radius>
          </cylinder>
        </geometry>
      </visual>
      <visual name='base_link_fixed_joint_lump__wheel_left_visual_12'>
        <pose frame=''>0 -0.24 0.065 1.5708 -0 0</pose>
        <geometry>
          <cylinder>
            <length>0.04</length>
            <radius>0.06</radius>
          </cylinder>
        </geometry>
      </visual>
      <visual name='base_link_fixed_joint_lump__wheel_right_visual_13'>
        <pose frame=''>0 0.24 0.065 1.5708 -0 0</pose>
        <geometry>
          <cylinder>
            <length>0.04</length>
            <radius>0.06</radius>
          </cylinder>
        </geometry>
      </visual>
    </link>
    <link name='head_link1'>
      <pose frame=''>0 0 1.33 0 -0 0</pose>
      <inertial>
        <pose frame=''>0 0 0 0 -0 0</pose>
        <mass>0.15</mass>
        <inertia>
          <ixx>0.03</ixx>
          <ixy>0</ixy>
          <ixz>0</ixz>
          <iyy>0.03</iyy>
          <iyz>0</iyz>
          <izz>0.03</izz>
        </inertia>
      </inertial>
      <visual name='head_link1_visual'>
        <pose frame=''>0 0 -0.1 0 -0 0</pose>
        <geometry>
          <box>
            <size>0.04 0.04 0.2</size>
          </box>
        </geometry>
      </visual>
    </link>
    <joint name='pan_connect' type='revolute'>
      <child>head_link1</child>
      <parent>base_link</parent>
      <axis>
        <xyz>0 0 1</xyz>
        <limit>
          <lower>-3</lower>
          <upper>3</upper>
          <effort>1000</effort>
          <velocity>10</velocity>
        </limit>
        <dynamics>
          <damping>0.1</damping>
          <friction>0</friction>
          <spring_reference>0</spring_reference>
          <spring_stiffness>0</spring_stiffness>
        </dynamics>
        <use_parent_model_frame>1</use_parent_model_frame>
      </axis>
    </joint>
    <link name='head_link2'>
      <pose frame=''>0 0 1.385 0 -0 0</pose>
      <inertial>
        <pose frame=''>0 0 0.025 0 -0 0</pose>
        <mass>0.3</mass>
        <inertia>
          <ixx>0.0601875</ixx>
          <ixy>0</ixy>
          <ixz>0</ixz>
          <iyy>0.0601875</iyy>
          <iyz>0</iyz>
          <izz>0.06</izz>
        </inertia>
      </inertial>
      <visual name='head_link2_visual'>
        <pose frame=''>0 0 0 1.5708 -0 0</pose>
        <geometry>
          <box>
            <size>0.03 0.03 0.03</size>
          </box>
        </geometry>
      </visual>
      <visual name='head_link2_fixed_joint_lump__kinect_link_visual_1'>
        <pose frame=''>0 0 0.05 0 -0 0</pose>
        <geometry>
          <box>
            <size>0.058 0.207 0.04</size>
          </box>
        </geometry>
        <material>
          <script>
            <uri>__default__</uri>
            <name>__default__</name>
          </script>
        </material>
      </visual>
      <gravity>1</gravity>
      <velocity_decay/>
      <sensor name='kinect_camera' type='depth'>
        <update_rate>30</update_rate>
        <visualize>1</visualize>
        <always_on>1</always_on>
        <camera name='__default__'>
          <horizontal_fov>1.0472</horizontal_fov>
          <image>
            <width>640</width>
            <height>480</height>
            <format>B8G8R8</format>
          </image>
          <clip>
            <near>0.1</near>
            <far>100</far>
          </clip>
        </camera>
        <plugin name='kinect_controller' filename='libgazebo_ros_openni_kinect.so'>
          <baseline>0.2</baseline>
          <alwaysOn>1</alwaysOn>
          <updateRate>0.0</updateRate>
          <cameraName>kinect</cameraName>
          <imageTopicName>rgb/image_raw</imageTopicName>
          <cameraInfoTopicName>rgb/camera_info</cameraInfoTopicName>
          <depthImageTopicName>depth/image_raw</depthImageTopicName>
          <depthImageCameraInfoTopicName>depth/camera_info</depthImageCameraInfoTopicName>
          <pointCloudTopicName>points</pointCloudTopicName>
          <frameName>kinect_link</frameName>
          <pointCloudCutoffMax>3.5</pointCloudCutoffMax>
          <pointCloudCutoff>0.5</pointCloudCutoff>
          <CxPrime>0</CxPrime>
          <Cx>0</Cx>
          <Cy>0</Cy>
          <focalLength>0</focalLength>
          <hackBaseline>0</hackBaseline>
        </plugin>
        <pose frame=''>0 0 0.05 0 -0 0</pose>
      </sensor>
    </link>
    <joint name='tilt_connect' type='revolute'>
      <child>head_link2</child>
      <parent>head_link1</parent>
      <axis>
        <xyz>0 1 0</xyz>
        <limit>
          <lower>-3</lower>
          <upper>3</upper>
          <effort>1000</effort>
          <velocity>10</velocity>
        </limit>
        <dynamics>
          <damping>0.1</damping>
          <friction>0</friction>
          <spring_reference>0</spring_reference>
          <spring_stiffness>0</spring_stiffness>
        </dynamics>
        <use_parent_model_frame>1</use_parent_model_frame>
      </axis>
    </joint>
    <link name='left_arm_link1'>
      <pose frame=''>-0 0.235 1.175 3.14159 1.57079 3.14159</pose>
      <inertial>
        <pose frame=''>0.0403 -0.015 0 0 -0 0</pose>
        <mass>0.35</mass>
        <inertia>
          <ixx>0.3</ixx>
          <ixy>0</ixy>
          <ixz>0</ixz>
          <iyy>0.3</iyy>
          <iyz>0</iyz>
          <izz>0.3</izz>
        </inertia>
      </inertial>
      <visual name='left_arm_link1_visual'>
        <pose frame=''>0.0403 -0.015 0 0 -0 0</pose>
        <geometry>
          <box>
            <size>0.07 0.08 0.05</size>
          </box>
        </geometry>
      </visual>
    </link>
    <joint name='la_1_joint' type='revolute'>
      <child>left_arm_link1</child>
      <parent>base_link</parent>
      <axis>
        <xyz>0 -1 0</xyz>
        <limit>
          <lower>-3</lower>
          <upper>3</upper>
          <effort>1000</effort>
          <velocity>10</velocity>
        </limit>
        <dynamics>
          <damping>0.5</damping>
          <friction>0</friction>
          <spring_reference>0</spring_reference>
          <spring_stiffness>0</spring_stiffness>
        </dynamics>
        <use_parent_model_frame>1</use_parent_model_frame>
      </axis>
    </joint>
    <link name='left_arm_link2'>
      <pose frame=''>-0 0.235 1.1147 3.14159 1.57079 3.14159</pose>
      <inertial>
        <pose frame=''>0.105 0 0 0 -0 0</pose>
        <mass>0.2</mass>
        <inertia>
          <ixx>0.3</ixx>
          <ixy>0</ixy>
          <ixz>0</ixz>
          <iyy>0.3</iyy>
          <iyz>0</iyz>
          <izz>0.3</izz>
        </inertia>
      </inertial>
      <visual name='left_arm_link2_visual'>
        <pose frame=''>0.105 0 0 0 -0 0</pose>
        <geometry>
          <box>
            <size>0.21 0.04 0.04</size>
          </box>
        </geometry>
      </visual>
    </link>
    <joint name='la_2_joint' type='revolute'>
      <child>left_arm_link2</child>
      <parent>left_arm_link1</parent>
      <axis>
        <xyz>-1 0 4e-06</xyz>
        <limit>
          <lower>-3</lower>
          <upper>3</upper>
          <effort>1000</effort>
          <velocity>10</velocity>
        </limit>
        <dynamics>
          <damping>0.5</damping>
          <friction>0</friction>
          <spring_reference>0</spring_reference>
          <spring_stiffness>0</spring_stiffness>
        </dynamics>
        <use_parent_model_frame>1</use_parent_model_frame>
      </axis>
    </joint>
    <link name='left_arm_link3'>
      <pose frame=''>-0 0.235 1.1147 3.14159 1.57079 3.14159</pose>
      <inertial>
        <pose frame=''>0.21 0 0 0 -0 0</pose>
        <mass>0.18</mass>
        <inertia>
          <ixx>0.3</ixx>
          <ixy>0</ixy>
          <ixz>0</ixz>
          <iyy>0.3</iyy>
          <iyz>0</iyz>
          <izz>0.3</izz>
        </inertia>
      </inertial>
      <visual name='left_arm_link3_visual'>
        <pose frame=''>0.21 0 0 0 -0 0</pose>
        <geometry>
          <box>
            <size>0.075 0.05 0.05</size>
          </box>
        </geometry>
      </visual>
    </link>
    <joint name='la_3_joint' type='revolute'>
      <child>left_arm_link3</child>
      <parent>left_arm_link2</parent>
      <axis>
        <xyz>-4e-06 0 -1</xyz>
        <limit>
          <lower>-3</lower>
          <upper>3</upper>
          <effort>1000</effort>
          <velocity>10</velocity>
        </limit>
        <dynamics>
          <damping>0.5</damping>
          <friction>0</friction>
          <spring_reference>0</spring_reference>
          <spring_stiffness>0</spring_stiffness>
        </dynamics>
        <use_parent_model_frame>1</use_parent_model_frame>
      </axis>
    </joint>
    <link name='left_arm_link4'>
      <pose frame=''>-1e-06 0.235 0.8447 3.14159 1.57079 3.14159</pose>
      <inertial>
        <pose frame=''>0.09 0 0 0 -0 0</pose>
        <mass>0.18</mass>
        <inertia>
          <ixx>0.3</ixx>
          <ixy>0</ixy>
          <ixz>0</ixz>
          <iyy>0.3</iyy>
          <iyz>0</iyz>
          <izz>0.3</izz>
        </inertia>
      </inertial>
      <visual name='left_arm_link4_visual'>
        <pose frame=''>0.09 0 0 0 -0 0</pose>
        <geometry>
          <box>
            <size>0.18 0.04 0.04</size>
          </box>
        </geometry>
      </visual>
    </link>
    <joint name='la_4_joint' type='revolute'>
      <child>left_arm_link4</child>
      <parent>left_arm_link3</parent>
      <axis>
        <xyz>0 -1 0</xyz>
        <limit>
          <lower>-3</lower>
          <upper>3</upper>
          <effort>1000</effort>
          <velocity>10</velocity>
        </limit>
        <dynamics>
          <damping>0.5</damping>
          <friction>0</friction>
          <spring_reference>0</spring_reference>
          <spring_stiffness>0</spring_stiffness>
        </dynamics>
        <use_parent_model_frame>1</use_parent_model_frame>
      </axis>
    </joint>
    <link name='left_arm_link5'>
      <pose frame=''>-1e-06 0.235 0.8447 3.14159 1.57079 3.14159</pose>
      <inertial>
        <pose frame=''>0.18 0 0 0 -0 0</pose>
        <mass>0.18</mass>
        <inertia>
          <ixx>0.3</ixx>
          <ixy>0</ixy>
          <ixz>0</ixz>
          <iyy>0.3</iyy>
          <iyz>0</iyz>
          <izz>0.3</izz>
        </inertia>
      </inertial>
      <visual name='left_arm_link5_visual'>
        <pose frame=''>0.18 0 0 0 -0 0</pose>
        <geometry>
          <box>
            <size>0.045 0.05 0.05</size>
          </box>
        </geometry>
      </visual>
    </link>
    <joint name='la_5_joint' type='revolute'>
      <child>left_arm_link5</child>
      <parent>left_arm_link4</parent>
      <axis>
        <xyz>-4e-06 0 -1</xyz>
        <limit>
          <lower>-3</lower>
          <upper>3</upper>
          <effort>1000</effort>
          <velocity>10</velocity>
        </limit>
        <dynamics>
          <damping>0.5</damping>
          <friction>0</friction>
          <spring_reference>0</spring_reference>
          <spring_stiffness>0</spring_stiffness>
        </dynamics>
        <use_parent_model_frame>1</use_parent_model_frame>
      </axis>
    </joint>
    <link name='left_arm_link6'>
      <pose frame=''>-2e-06 0.235 0.6321 3.14159 1.57079 3.14159</pose>
      <inertial>
        <pose frame=''>0.05 0 0 0 -0 0</pose>
        <mass>0.15</mass>
        <inertia>
          <ixx>0.3</ixx>
          <ixy>0</ixy>
          <ixz>0</ixz>
          <iyy>0.3</iyy>
          <iyz>0</iyz>
          <izz>0.3</izz>
        </inertia>
      </inertial>
      <visual name='left_arm_link6_visual'>
        <pose frame=''>0.05 0 0 0 -0 0</pose>
        <geometry>
          <box>
            <size>0.1 0.04 0.04</size>
          </box>
        </geometry>
      </visual>
    </link>
    <joint name='la_6_joint' type='revolute'>
      <child>left_arm_link6</child>
      <parent>left_arm_link5</parent>
      <axis>
        <xyz>0 -1 0</xyz>
        <limit>
          <lower>-3</lower>
          <upper>3</upper>
          <effort>1000</effort>
          <velocity>10</velocity>
        </limit>
        <dynamics>
          <damping>0.5</damping>
          <friction>0</friction>
          <spring_reference>0</spring_reference>
          <spring_stiffness>0</spring_stiffness>
        </dynamics>
        <use_parent_model_frame>1</use_parent_model_frame>
      </axis>
    </joint>
    <link name='left_arm_link7'>
      <pose frame=''>-2e-06 0.235 0.6321 3.14159 1.57079 3.14159</pose>
      <inertial>
        <pose frame=''>0.186667 0 0 0 -0 0</pose>
        <mass>0.45</mass>
        <inertia>
          <ixx>0.90048</ixx>
          <ixy>0</ixy>
          <ixz>0</ixz>
          <iyy>0.90169</iyy>
          <iyz>0</iyz>
          <izz>0.90217</izz>
        </inertia>
      </inertial>
      <visual name='left_arm_link7_visual'>
        <pose frame=''>0.1 0 0 0 -0 0</pose>
        <geometry>
          <box>
            <size>0.06 0.04 0.04</size>
          </box>
        </geometry>
      </visual>
      <visual name='left_arm_link7_fixed_joint_lump__left_arm_grip_center_visual_1'>
        <pose frame=''>0.13 0 0 0 -0 0</pose>
        <geometry>
          <box>
            <size>0.04 0.1 0.04</size>
          </box>
        </geometry>
      </visual>
      <visual name='left_arm_link7_fixed_joint_lump__left_arm_grip_left_visual_2'>
        <pose frame=''>0.195 -0.04 0 0 -0 0</pose>
        <geometry>
          <box>
            <size>0.13 0.015 0.03</size>
          </box>
        </geometry>
      </visual>
      <visual name='left_arm_link7_fixed_joint_lump__left_arm_grip_right_visual_3'>
        <pose frame=''>0.195 0.04 0 0 -0 0</pose>
        <geometry>
          <box>
            <size>0.13 0.015 0.03</size>
          </box>
        </geometry>
      </visual>
    </link>
    <joint name='la_7_joint' type='revolute'>
      <child>left_arm_link7</child>
      <parent>left_arm_link6</parent>
      <axis>
        <xyz>-4e-06 0 -1</xyz>
        <limit>
          <lower>-3</lower>
          <upper>3</upper>
          <effort>1000</effort>
          <velocity>10</velocity>
        </limit>
        <dynamics>
          <damping>0.5</damping>
          <friction>0</friction>
          <spring_reference>0</spring_reference>
          <spring_stiffness>0</spring_stiffness>
        </dynamics>
        <use_parent_model_frame>1</use_parent_model_frame>
      </axis>
    </joint>
    <link name='right_arm_link1'>
      <pose frame=''>-0 -0.235 1.175 3.14159 1.57079 3.14159</pose>
      <inertial>
        <pose frame=''>0.0403 0.015 0 0 -0 0</pose>
        <mass>0.35</mass>
        <inertia>
          <ixx>0.3</ixx>
          <ixy>0</ixy>
          <ixz>0</ixz>
          <iyy>0.3</iyy>
          <iyz>0</iyz>
          <izz>0.3</izz>
        </inertia>
      </inertial>
      <visual name='right_arm_link1_visual'>
        <pose frame=''>0.0403 0.015 0 0 -0 0</pose>
        <geometry>
          <box>
            <size>0.07 0.08 0.05</size>
          </box>
        </geometry>
      </visual>
    </link>
    <joint name='ra_1_joint' type='revolute'>
      <child>right_arm_link1</child>
      <parent>base_link</parent>
      <axis>
        <xyz>0 -1 0</xyz>
        <limit>
          <lower>-3</lower>
          <upper>3</upper>
          <effort>1000</effort>
          <velocity>10</velocity>
        </limit>
        <dynamics>
          <damping>0.5</damping>
          <friction>0</friction>
          <spring_reference>0</spring_reference>
          <spring_stiffness>0</spring_stiffness>
        </dynamics>
        <use_parent_model_frame>1</use_parent_model_frame>
      </axis>
    </joint>
    <link name='right_arm_link2'>
      <pose frame=''>-0 -0.235 1.1147 3.14159 1.57079 3.14159</pose>
      <inertial>
        <pose frame=''>0.105 0 0 0 -0 0</pose>
        <mass>0.2</mass>
        <inertia>
          <ixx>0.3</ixx>
          <ixy>0</ixy>
          <ixz>0</ixz>
          <iyy>0.3</iyy>
          <iyz>0</iyz>
          <izz>0.3</izz>
        </inertia>
      </inertial>
      <visual name='right_arm_link2_visual'>
        <pose frame=''>0.105 0 0 0 -0 0</pose>
        <geometry>
          <box>
            <size>0.21 0.04 0.04</size>
          </box>
        </geometry>
      </visual>
    </link>
    <joint name='ra_2_joint' type='revolute'>
      <child>right_arm_link2</child>
      <parent>right_arm_link1</parent>
      <axis>
        <xyz>-1 0 4e-06</xyz>
        <limit>
          <lower>-3</lower>
          <upper>3</upper>
          <effort>1000</effort>
          <velocity>10</velocity>
        </limit>
        <dynamics>
          <damping>0.5</damping>
          <friction>0</friction>
          <spring_reference>0</spring_reference>
          <spring_stiffness>0</spring_stiffness>
        </dynamics>
        <use_parent_model_frame>1</use_parent_model_frame>
      </axis>
    </joint>
    <link name='right_arm_link3'>
      <pose frame=''>-0 -0.235 1.1147 3.14159 1.57079 3.14159</pose>
      <inertial>
        <pose frame=''>0.21 0 0 0 -0 0</pose>
        <mass>0.18</mass>
        <inertia>
          <ixx>0.3</ixx>
          <ixy>0</ixy>
          <ixz>0</ixz>
          <iyy>0.3</iyy>
          <iyz>0</iyz>
          <izz>0.3</izz>
        </inertia>
      </inertial>
      <visual name='right_arm_link3_visual'>
        <pose frame=''>0.21 0 0 0 -0 0</pose>
        <geometry>
          <box>
            <size>0.075 0.05 0.05</size>
          </box>
        </geometry>
      </visual>
    </link>
    <joint name='ra_3_joint' type='revolute'>
      <child>right_arm_link3</child>
      <parent>right_arm_link2</parent>
      <axis>
        <xyz>-4e-06 0 -1</xyz>
        <limit>
          <lower>-3</lower>
          <upper>3</upper>
          <effort>1000</effort>
          <velocity>10</velocity>
        </limit>
        <dynamics>
          <damping>0.5</damping>
          <friction>0</friction>
          <spring_reference>0</spring_reference>
          <spring_stiffness>0</spring_stiffness>
        </dynamics>
        <use_parent_model_frame>1</use_parent_model_frame>
      </axis>
    </joint>
    <link name='right_arm_link4'>
      <pose frame=''>-1e-06 -0.235 0.8447 3.14159 1.57079 3.14159</pose>
      <inertial>
        <pose frame=''>0.09 0 0 0 -0 0</pose>
        <mass>0.18</mass>
        <inertia>
          <ixx>0.3</ixx>
          <ixy>0</ixy>
          <ixz>0</ixz>
          <iyy>0.3</iyy>
          <iyz>0</iyz>
          <izz>0.3</izz>
        </inertia>
      </inertial>
      <visual name='right_arm_link4_visual'>
        <pose frame=''>0.09 0 0 0 -0 0</pose>
        <geometry>
          <box>
            <size>0.18 0.04 0.04</size>
          </box>
        </geometry>
      </visual>
    </link>
    <joint name='ra_4_joint' type='revolute'>
      <child>right_arm_link4</child>
      <parent>right_arm_link3</parent>
      <axis>
        <xyz>0 -1 0</xyz>
        <limit>
          <lower>-3</lower>
          <upper>3</upper>
          <effort>1000</effort>
          <velocity>10</velocity>
        </limit>
        <dynamics>
          <damping>0.5</damping>
          <friction>0</friction>
          <spring_reference>0</spring_reference>
          <spring_stiffness>0</spring_stiffness>
        </dynamics>
        <use_parent_model_frame>1</use_parent_model_frame>
      </axis>
    </joint>
    <link name='right_arm_link5'>
      <pose frame=''>-1e-06 -0.235 0.8447 3.14159 1.57079 3.14159</pose>
      <inertial>
        <pose frame=''>0.18 0 0 0 -0 0</pose>
        <mass>0.18</mass>
        <inertia>
          <ixx>0.3</ixx>
          <ixy>0</ixy>
          <ixz>0</ixz>
          <iyy>0.3</iyy>
          <iyz>0</iyz>
          <izz>0.3</izz>
        </inertia>
      </inertial>
      <visual name='right_arm_link5_visual'>
        <pose frame=''>0.18 0 0 0 -0 0</pose>
        <geometry>
          <box>
            <size>0.045 0.05 0.05</size>
          </box>
        </geometry>
      </visual>
    </link>
    <joint name='ra_5_joint' type='revolute'>
      <child>right_arm_link5</child>
      <parent>right_arm_link4</parent>
      <axis>
        <xyz>-4e-06 0 -1</xyz>
        <limit>
          <lower>-3</lower>
          <upper>3</upper>
          <effort>1000</effort>
          <velocity>10</velocity>
        </limit>
        <dynamics>
          <damping>0.5</damping>
          <friction>0</friction>
          <spring_reference>0</spring_reference>
          <spring_stiffness>0</spring_stiffness>
        </dynamics>
        <use_parent_model_frame>1</use_parent_model_frame>
      </axis>
    </joint>
    <link name='right_arm_link6'>
      <pose frame=''>-2e-06 -0.235 0.6321 3.14159 1.57079 3.14159</pose>
      <inertial>
        <pose frame=''>0.05 0 0 0 -0 0</pose>
        <mass>0.15</mass>
        <inertia>
          <ixx>0.3</ixx>
          <ixy>0</ixy>
          <ixz>0</ixz>
          <iyy>0.3</iyy>
          <iyz>0</iyz>
          <izz>0.3</izz>
        </inertia>
      </inertial>
      <visual name='right_arm_link6_visual'>
        <pose frame=''>0.05 0 0 0 -0 0</pose>
        <geometry>
          <box>
            <size>0.1 0.04 0.04</size>
          </box>
        </geometry>
      </visual>
    </link>
    <joint name='ra_6_joint' type='revolute'>
      <child>right_arm_link6</child>
      <parent>right_arm_link5</parent>
      <axis>
        <xyz>0 -1 0</xyz>
        <limit>
          <lower>-3</lower>
          <upper>3</upper>
          <effort>1000</effort>
          <velocity>10</velocity>
        </limit>
        <dynamics>
          <damping>0.5</damping>
          <friction>0</friction>
          <spring_reference>0</spring_reference>
          <spring_stiffness>0</spring_stiffness>
        </dynamics>
        <use_parent_model_frame>1</use_parent_model_frame>
      </axis>
    </joint>
    <link name='right_arm_link7'>
      <pose frame=''>-2e-06 -0.235 0.6321 3.14159 1.57079 3.14159</pose>
      <inertial>
        <pose frame=''>0.186667 0 0 0 -0 0</pose>
        <mass>0.45</mass>
        <inertia>
          <ixx>0.90048</ixx>
          <ixy>0</ixy>
          <ixz>0</ixz>
          <iyy>0.90169</iyy>
          <iyz>0</iyz>
          <izz>0.90217</izz>
        </inertia>
      </inertial>
      <visual name='right_arm_link7_visual'>
        <pose frame=''>0.1 0 0 0 -0 0</pose>
        <geometry>
          <box>
            <size>0.06 0.04 0.04</size>
          </box>
        </geometry>
      </visual>
      <visual name='right_arm_link7_fixed_joint_lump__right_arm_grip_center_visual_1'>
        <pose frame=''>0.13 0 0 0 -0 0</pose>
        <geometry>
          <box>
            <size>0.04 0.1 0.04</size>
          </box>
        </geometry>
      </visual>
      <visual name='right_arm_link7_fixed_joint_lump__right_arm_grip_left_visual_2'>
        <pose frame=''>0.195 -0.04 0 0 -0 0</pose>
        <geometry>
          <box>
            <size>0.13 0.015 0.03</size>
          </box>
        </geometry>
      </visual>
      <visual name='right_arm_link7_fixed_joint_lump__right_arm_grip_right_visual_3'>
        <pose frame=''>0.195 0.04 0 0 -0 0</pose>
        <geometry>
          <box>
            <size>0.13 0.015 0.03</size>
          </box>
        </geometry>
      </visual>
    </link>
    <joint name='ra_7_joint' type='revolute'>
      <child>right_arm_link7</child>
      <parent>right_arm_link6</parent>
      <axis>
        <xyz>-4e-06 0 -1</xyz>
        <limit>
          <lower>-3</lower>
          <upper>3</upper>
          <effort>1000</effort>
          <velocity>10</velocity>
        </limit>
        <dynamics>
          <damping>0.5</damping>
          <friction>0</friction>
          <spring_reference>0</spring_reference>
          <spring_stiffness>0</spring_stiffness>
        </dynamics>
        <use_parent_model_frame>1</use_parent_model_frame>
      </axis>
    </joint>
  </model>
</sdf>
